<?xml version='1.0'?>

<robot name="myrobot" xmlns:xacro="http://www.ros.org/wiki/xacro">

  <xacro:property name="cameraSize" value="0.05"/>
  <xacro:property name="cameraMass" value="0.1"/>

  <xacro:include filename="$(find mybot_description)/urdf/mybot.gazebo" />
  <xacro:include filename="$(find mybot_description)/urdf/materials.xacro" />
  <xacro:include filename="$(find mybot_description)/urdf/macros.xacro" />


  <link name='chassis'>
    <pose>0 0 0.1 0 0 0</pose>

    <inertial>
      <mass value="15.0"/>
      <origin xyz="0.0 0 0.1" rpy=" 0 0 0"/>
      <inertia
          ixx="0.1" ixy="0" ixz="0"
          iyy="0.1" iyz="0"
          izz="0.1"
      />
    </inertial>

    <collision name='collision'>
      <geometry>
        <box size=".4 .2 .1"/>
      </geometry>
    </collision>

    <visual name='chassis_visual'>
      <origin xyz="0 0 0" rpy=" 0 0 0"/>
      <geometry>
        <box size=".4 .2 .1"/>
      </geometry>
    </visual>


    <collision name='caster_collision'>
      <origin xyz="-0.15 0 -0.05" rpy=" 0 0 0"/>
      <geometry>
        <sphere radius="0.05"/>
      </geometry>
      <surface>
        <friction>
          <ode>
            <mu>0</mu>
            <mu2>0</mu2>
            <slip1>1.0</slip1>
            <slip2>1.0</slip2>
          </ode>
        </friction>
      </surface>
    </collision>

    <visual name='caster_visual'>
      <origin xyz="-0.15 0 -0.05" rpy=" 0 0 0"/>
      <geometry>
        <sphere radius="0.05"/>
      </geometry>
    </visual>

    <collision name='caster_front_collision'>
      <origin xyz="0.15 0 -0.05" rpy=" 0 0 0"/>
      <geometry>
        <sphere radius="0.05"/>
      </geometry>
      <surface>
        <friction>
          <ode>
            <mu>0</mu>
            <mu2>0</mu2>
            <slip1>1.0</slip1>
            <slip2>1.0</slip2>
          </ode>
        </friction>
      </surface>
    </collision>

    <visual name='caster_front_visual'>
      <origin xyz="0.15 0 -0.05" rpy=" 0 0 0"/>
      <geometry>
        <sphere radius="0.05"/>
      </geometry>
    </visual>

  </link>

      <link name="base_link">
        
<inertial>
            <origin xyz="0.00078394 -0.00078007 0.036251" rpy="0 0 0" />
            <mass value="0.35184" />
            <inertia ixx="0.00085551" ixy="3.9719E-05" ixz="-8.5247E-07" iyy="0.00085359" iyz="8.7202E-07" izz="0.0015197" />
        </inertial>

        <visual>
            <origin xyz="0 0 0" rpy="0 0 0" />
            <geometry>
                <mesh filename="package://tu_nguyen/meshes/base_link.STL" />
            </geometry>
            <material name="">
                <color rgba="0.74902 0.74902 0.74902 1" />
            </material>
        </visual>
        <collision>
            <origin xyz="0 0 0" rpy="0 0 0" />
            <geometry>
                <mesh filename="package://tu_nguyen/meshes/base_link.STL" />
            </geometry>
        </collision>
    </link>
  <joint name="arm_joint" type="fixed">
      <axis xyz="0 0 0" />
      <origin xyz="-0.05 0 .05" rpy="0 0 0"/>
      <parent link="chassis"/>
      <child link="base_link"/>
    </joint>

    <link name="link_1">
        
      <inertial>
            <origin xyz="3.4402E-05 0.011453 0.016551" rpy="0 0 0" />
            <mass value="0.17883" />
            <inertia ixx="0.0001965" ixy="2.8865E-09" ixz="2.0476E-08" iyy="0.00018359" iyz="-6.3455E-06" izz="0.0003234" />
        </inertial>

        <visual>
            <origin xyz="0 0 0" rpy="0 0 0" />
            <geometry>
                <mesh filename="package://tu_nguyen/meshes/link_1.STL" />
            </geometry>
            <material name="">
                <color rgba="0.74902 0.74902 0.74902 1" />
            </material>
        </visual>
        <collision>
            <origin xyz="0 0 0" rpy="0 0 0" />
            <geometry>
                <mesh filename="package://tu_nguyen/meshes/link_1.STL" />
            </geometry>
        </collision>
    </link>
    <joint name="joint_1" type="revolute">
        <origin xyz="0 0 0.06" rpy="0 0 0" />
        <parent link="base_link" />
        <child link="link_1" />
        <axis xyz="0 0 1" />
        <limit lower="-3.14" upper="3.14" effort="300" velocity="1" />
    </joint>
    <link name="link_2">
        
<inertial>
            <origin xyz="3.6013E-07 0.023022 0.056301" rpy="0 0 0" />
            <mass value="0.073669" />
            <inertia ixx="0.00011985" ixy="4.0562E-11" ixz="1.6465E-10" iyy="0.0001173" iyz="-3.611E-07" izz="1.434E-05" />
        </inertial>

        <visual>
            <origin xyz="0 0 0" rpy="0 0 0" />
            <geometry>
                <mesh filename="package://tu_nguyen/meshes/link_2.STL" />
            </geometry>
            <material name="">
                <color rgba="0.74902 0.74902 0.74902 1" />
            </material>
        </visual>
        <collision>
            <origin xyz="0 0 0" rpy="0 0 0" />
            <geometry>
                <mesh filename="package://tu_nguyen/meshes/link_2.STL" />
            </geometry>
        </collision>
    </link>
    <joint name="joint_2" type="revolute">
        <origin xyz="0.00010548 -0.024031 0.044" rpy="0 0 0" />
        <parent link="link_1" />
        <child link="link_2" />
        <axis xyz="0 1 0" />
        <limit lower="-1.708" upper="1.708" effort="300" velocity="1" />
    </joint>
    <link name="link_3">
        
<inertial>
            <origin xyz="-3.96617753665222E-06 0.0291072422360279 0.0569268959166495" rpy="0 0 0" />
            <mass value="0.0853549537054368" />
            <inertia ixx="5.06192462099083E-05" ixy="-3.09386216016138E-11" ixz="-1.3594525196218E-08" iyy="5.28546441510861E-05" iyz="3.20776653060743E-08" izz="5.15582429795402E-06" />
        </inertial>

        <visual>
            <origin xyz="0 0 0" rpy="0 0 0" />
            <geometry>
                <mesh filename="package://tu_nguyen/meshes/link_3.STL" />
            </geometry>
            <material name="">
                <color rgba="0.749019607843137 0.749019607843137 0.749019607843137 1" />
            </material>
        </visual>
        <collision>
            <origin xyz="0 0 0" rpy="0 0 0" />
            <geometry>
                <mesh filename="package://tu_nguyen/meshes/link_3.STL" />
            </geometry>
        </collision>
    </link>
    <joint name="joint_3" type="revolute">
        <origin xyz="0 0 0.12194" rpy="0 0 0" />
        <parent link="link_2" />
        <child link="link_3" />
        <axis xyz="0 1 0" />
        <limit lower="-1.708" upper="1.708" effort="300" velocity="1" />
    </joint>
    <link name="link_4">
        
<inertial>
            <origin xyz="-0.0120735458637133 0.036074545399959 0.0579060953746561" rpy="0 0 0" />
            <mass value="0.0614391558855416" />
            <inertia ixx="2.8354849567181E-05" ixy="9.2995830866633E-08" ixz="2.44976833545897E-10" iyy="1.17555381784956E-05" iyz="-4.17687884392995E-07" izz="2.0099784279376E-05" />
        </inertial>

        <visual>
            <origin xyz="0 0 0" rpy="0 0 0" />
            <geometry>
                <mesh filename="package://tu_nguyen/meshes/link_4.STL" />
            </geometry>
            <material name="">
                <color rgba="0.749019607843137 0.749019607843137 0.749019607843137 1" />
            </material>
        </visual>
        <collision>
            <origin xyz="0 0 0" rpy="0 0 0" />
            <geometry>
                <mesh filename="package://tu_nguyen/meshes/link_4.STL" />
            </geometry>
        </collision>
    </link>
    <joint name="joint_4" type="revolute">
        <origin xyz="0 0 0.114" rpy="0 0 0" />
        <parent link="link_3" />
        <child link="link_4" />
        <axis xyz="0 1 0" />
        <limit lower="-1.708" upper="1.708" effort="300" velocity="1" />
    </joint>
    <link name="link_51">
        
<inertial>
            <origin xyz="0.00149998785731969 -0.00291234349816738 0.0342421582199686" rpy="0 0 0" />
            <mass value="0.00475482638149408" />
            <inertia ixx="4.94751489323072E-06" ixy="6.03151233825932E-13" ixz="2.32482274648162E-12" iyy="4.41447487378701E-06" iyz="-5.04499946684658E-07" izz="5.4368013054544E-07" />
        </inertial>

        <visual>
            <origin xyz="0 0 0" rpy="0 0 0" />
            <geometry>
                <mesh filename="package://tu_nguyen/meshes/link_51.STL" />
            </geometry>
            <material name="">
                <color rgba="0.749019607843137 0.749019607843137 0.749019607843137 1" />
            </material>
        </visual>
        <collision>
            <origin xyz="0 0 0" rpy="0 0 0" />
            <geometry>
                <mesh filename="package://tu_nguyen/meshes/link_51.STL" />
            </geometry>
        </collision>
    </link>
    <joint name="joint_51" type="revolute">
        <origin xyz="0.0015 0.0096756 0.07625" rpy="0 0 0" />
        <parent link="link_4" />
        <child link="link_51" />
        <axis xyz="1 0 0" />
        <limit lower="0" upper="0.4" effort="300" velocity="1" />
    </joint>
    <link name="link_52">
        
<inertial>
            <origin xyz="0.00150001214059608 0.00290820241921078 0.0342746337461361" rpy="0 0 0" />
            <mass value="0.00475475613653127" />
            <inertia ixx="4.93711727641837E-06" ixy="6.02977678312998E-13" ixz="-2.32505912287766E-12" iyy="4.40383720688213E-06" iyz="5.04733188504208E-07" izz="5.43920075735643E-07" />
        </inertial>

        <visual>
            <origin xyz="0 0 0" rpy="0 0 0" />
            <geometry>
                <mesh filename="package://tu_nguyen/meshes/link_52.STL" />
            </geometry>
            <material name="">
                <color rgba="0.749019607843137 0.749019607843137 0.749019607843137 1" />
            </material>
        </visual>
        <collision>
            <origin xyz="0 0 0" rpy="0 0 0" />
            <geometry>
                <mesh filename="package://tu_nguyen/meshes/link_52.STL" />
            </geometry>
        </collision>
    </link>
    <joint name="joint_52" type="revolute">
        <origin xyz="0.0015 0.036676 0.07625" rpy="0 0 0" />
        <parent link="link_4" />
        <child link="link_52" />
        <axis xyz="1 0 0" />
        <limit lower="-0.4" upper="0" effort="300" velocity="1" />
    </joint>
    

    <transmission name="trans_joint_1">
        <type>transmission_interface/SimpleTransmission</type>
        <joint name="joint_1">
            <hardwareInterface>hardware_interface/PositionJointInterface</hardwareInterface>
        </joint>
        <actuator name="joint_1_motor">
            <hardwareInterface>hardware_interface/PositionJointInterface</hardwareInterface>
            <mechanicalReduction>1</mechanicalReduction>
        </actuator>
    </transmission>
    <transmission name="trans_joint_2">
        <type>transmission_interface/SimpleTransmission</type>  
        <joint name="joint_2">
            <hardwareInterface>hardware_interface/PositionJointInterface</hardwareInterface>
        </joint>
        <actuator name="joint_2_motor">
            <hardwareInterface>hardware_interface/PositionJointInterface</hardwareInterface>
            <mechanicalReduction>1</mechanicalReduction>
        </actuator>
    </transmission>
    <transmission name="trans_joint_3">
        <type>transmission_interface/SimpleTransmission</type>
        <joint name="joint_3">
            <hardwareInterface>hardware_interface/PositionJointInterface</hardwareInterface>
        </joint>
        <actuator name="joint_3_motor">
            <hardwareInterface>hardware_interface/PositionJointInterface</hardwareInterface>
            <mechanicalReduction>1</mechanicalReduction>
        </actuator>
    </transmission>
    <transmission name="trans_joint_4">
        <type>transmission_interface/SimpleTransmission</type>
        <joint name="joint_4">
            <hardwareInterface>hardware_interface/PositionJointInterface</hardwareInterface>
        </joint>
        <actuator name="joint_4_motor">
            <hardwareInterface>hardware_interface/PositionJointInterface</hardwareInterface>
            <mechanicalReduction>1</mechanicalReduction>
        </actuator>
    </transmission>
    

    <gazebo>
        <plugin name="gazebo_ros_control" filename="libgazebo_ros_control.so">
            
        </plugin>
    </gazebo>

  <link name="left_wheel">
    <!--origin xyz="0.1 0.13 0.1" rpy="0 1.5707 1.5707"/-->
    <collision name="collision">
      <origin xyz="0 0 0" rpy="0 1.5707 1.5707"/>
      <geometry>
        <cylinder radius="0.1" length="0.05"/>
      </geometry>
    </collision>
    <visual name="left_wheel_visual">
      <origin xyz="0 0 0" rpy="0 1.5707 1.5707"/>
      <geometry>
        <cylinder radius="0.1" length="0.05"/>
      </geometry>
    </visual>
    <inertial>
      <origin xyz="0 0 0" rpy="0 1.5707 1.5707"/>
      <mass value="5"/>
      <inertia
        ixx=".1" ixy="0.0" ixz="0.0"
        iyy=".1" iyz="0.0"
        izz=".1"/>
    </inertial>
  </link>

  <link name="right_wheel">
    <!--origin xyz="0.1 -0.13 0.1" rpy="0 1.5707 1.5707"/-->
    <collision name="collision">
      <origin xyz="0 0 0" rpy="0 1.5707 1.5707"/>
      <geometry>
        <cylinder radius="0.1" length="0.05"/>
      </geometry>
    </collision>
    <visual name="right_wheel_visual">
      <origin xyz="0 0 0" rpy="0 1.5707 1.5707"/>
      <geometry>
        <cylinder radius="0.1" length="0.05"/>
      </geometry>
    </visual>
    <inertial>
      <origin xyz="0 0 0" rpy="0 1.5707 1.5707"/>
      <mass value="5"/>
      <inertia
        ixx=".1" ixy="0.0" ixz="0.0"
        iyy=".1" iyz="0.0"
        izz=".1"/>
    </inertial>
  </link>


  <joint type="continuous" name="left_wheel_hinge">
    <origin xyz="0 0.15 0" rpy="0 0 0"/>
    <!--origin xyz="0.1 0.13 0" rpy="0 1.5707 1.5707"/-->
    <child link="left_wheel"/>
    <parent link="chassis"/>
    <axis xyz="0 1 0" rpy="0 0 0"/>
    <limit effort="10000" velocity="1000"/>
    <joint_properties damping="1.0" friction="1.0"/>
  </joint>

  <joint type="continuous" name="right_wheel_hinge">
    <origin xyz="0 -0.15 0" rpy="0 0 0"/>
    <!--origin xyz="0.1 -0.13 0" rpy="0 1.5707 1.5707"/-->
    <child link="right_wheel"/>
    <parent link="chassis"/>
    <axis xyz="0 1 0" rpy="0 0 0"/>
    <limit effort="10000" velocity="1000"/>
    <joint_properties damping="1.0" friction="1.0"/>
  </joint>


  <link name="camera">
    <collision>
      <origin xyz="0 0 0" rpy="0 0 0"/>
      <geometry>
        <box size="${cameraSize} ${cameraSize} ${cameraSize}"/>
      </geometry>
    </collision>

    <visual>
      <origin xyz="0 0 0" rpy="0 0 0"/>
      <geometry>
        <box size="${cameraSize} ${cameraSize} ${cameraSize}"/>
      </geometry>
      <material name="green"/>
    </visual>

    <inertial>
      <mass value="${cameraMass}" />
      <origin xyz="0 0 0" rpy="0 0 0"/>
      <box_inertia m="${cameraMass}" x="${cameraSize}" y="${cameraSize}" z="${cameraSize}" />
      <inertia ixx="1e-6" ixy="0" ixz="0" iyy="1e-6" iyz="0" izz="1e-6" />
    </inertial>
  </link>

  <joint name="camera_joint" type="fixed">
    <axis xyz="0 1 0" />
    <origin xyz=".2 0 0" rpy="0 0 0"/>
    <parent link="chassis"/>
    <child link="camera"/>
  </joint>


  <joint name="laser_joint" type="fixed">
    <axis xyz="0 1 0" />
    <origin xyz=".15 0 .1" rpy="0 0 0"/>
    <parent link="chassis"/>
    <child link="sensor_laser"/>
  </joint>

  <!-- Hokuyo Laser -->
  <link name="sensor_laser">
    <collision>
      <origin xyz="0 0 0" rpy="0 0 0"/>
      <geometry>
    <box size="0.1 0.1 0.1"/>
      </geometry>
    </collision>

    <visual>
      <origin xyz="0 0 0" rpy="0 0 0"/>
      <geometry>
        <!--<mesh filename="package://mybot_description/meshes/hokuyo.dae"/> -->
         <cylinder radius="0.05" length="0.1"/>
      </geometry>
    </visual>

    <inertial>
      <mass value="1e-5" />
      <origin xyz="0 0 0" rpy="0 0 0"/>
      <inertia ixx="1e-6" ixy="0" ixz="0" iyy="1e-6" iyz="0" izz="1e-6" />
    </inertial>
  </link>

    <link name="imu_link"/>
    <joint name="imu_joint" type="fixed">
      <origin xyz="0.15 0 0.05" rpy="0 0 0" />
      <parent link="chassis" />
      <child link="imu_link" />
    </joint>
    <gazebo reference="imu_link">
    </gazebo>

    <link name="gps_link"/>
    <joint name="gps_joint" type="fixed">
      <origin xyz="0.15 0 0.05" rpy="0 0 0" />
      <parent link="chassis" />
      <child link="gps_link" />
    </joint>
    <gazebo reference="gps_link">
    </gazebo>

</robot>

